<?xml version="1.0"?>
<robot xmlns:xacro="http://www.ros.org/wiki/xacro"  name="robot">

    <xacro:include filename="inertial_macros.xacro"/>

    <material name="white">
        <color rgba ="1 1 1 1" />
    </material>    

    <material name="orange">
        <color rgba ="1 0.3 0.1 1" />
    </material> 

    <material name="blue">
        <color rgba ="0.2 0.2 1 1" />
    </material> 

    <material name="black">
        <color rgba ="0 0 0 1" />
    </material> 

    <!-- BASE LINK -->

    <link name="base_link">

    </link>

    <!-- CHASSIS LINK-->

    <joint name="chassis_joint" type="fixed">
        <parent link="base_link"/>
        <child link="chassis"/>
        <origin xyz="-0.1 0 0"/>
    </joint>

    <link name="chassis">
        <visual>
            <origin xyz="0.325 0 0.075"/>
            <geometry>
                <box size="0.65 0.45 0.15"/>
            </geometry>
            <material name="white"/>
        </visual>
        <collision>
            <origin xyz="0.325 0 0.075"/>
            <geometry>
                <box size="0.65 0.45 0.15"/>
            </geometry>
            <material name="white"/>
        </collision>
        <xacro:inertial_box mass="0.5" x="0.3" y="0.3" z="0.15">
            <origin xyz="0.325 0 0.075" rpy="0 0 0"/>
        </xacro:inertial_box>
    </link>

    <!-- LEFT WHEEL LINK-->

    <joint name="left_wheel_joint" type="continuous">
        <parent link="base_link"/>
        <child link="left_wheel"/>
        <origin xyz="0 0.25 0" rpy="-${pi/2} 0 0"/>
        <axis xyz="0 0 1"/>
    </joint>

    <link name="left_wheel">
        <visual>
            <geometry>
                <cylinder radius="0.06" length="0.04"/>
            </geometry>
            <material name="black"/>
        </visual>
        <collision>
            <geometry>
                <cylinder radius="0.06" length="0.04"/>
            </geometry>
            <material name="black"/>
        </collision>
        <xacro:inertial_cylinder mass="0.1" length="0.04" radius="0.06">
            <origin xyz="0 0 0" rpy="0 0 0"/>
        </xacro:inertial_cylinder>
    </link>

    <!-- RIGHT WHEEL LINK-->

    <joint name="right_wheel_joint" type="continuous">
        <parent link="base_link"/>
        <child link="right_wheel"/>
        <origin xyz="0 -0.25 0" rpy="${pi/2} 0 0"/>
        <axis xyz="0 0 -1"/>
    </joint>

    <link name="right_wheel">
        <visual>
            <geometry>
                <cylinder radius="0.06" length="0.04"/>
            </geometry>
            <material name="black"/>
        </visual>
        <collision>
            <geometry>
                <cylinder radius="0.06" length="0.04"/>
            </geometry>
            <material name="black"/>
        </collision>
        <xacro:inertial_cylinder mass="0.1" length="0.04" radius="0.06">
            <origin xyz="0 0 0" rpy="0 0 0"/>
        </xacro:inertial_cylinder>
    </link>

    <!-- FRONT LEFT WHEEL LINK-->

    <joint name="front_left_wheel_joint" type="continuous">
        <parent link="base_link"/>
        <child link="front_left_wheel"/>
        <origin xyz="0.4 0.25 0" rpy="-${pi/2} 0 0"/>
        <axis xyz="0 0 1"/>
    </joint>

    <link name="front_left_wheel">
        <visual>
            <geometry>
                <cylinder radius="0.06" length="0.04"/>
            </geometry>
            <material name="blue"/>
        </visual>
        <collision>
            <geometry>
                <cylinder radius="0.06" length="0.04"/>
            </geometry>
            <material name="blue"/>
        </collision>
        <xacro:inertial_cylinder mass="0.1" length="0.04" radius="0.06">
            <origin xyz="0 0 0" rpy="0 0 0"/>
        </xacro:inertial_cylinder>
    </link>

    <!-- FRONT RIGHT WHEEL LINK-->

    <joint name="front_right_wheel_joint" type="continuous"> 
        <parent link="base_link"/>
        <child link="front_right_wheel"/>
        <origin xyz="0.4 -0.25 0" rpy="${pi/2} 0 0"/>
        <axis xyz="0 0 -1"/>
    </joint>

    <link name="front_right_wheel">
        <visual>
            <geometry>
                <cylinder radius="0.06" length="0.04"/>
            </geometry>
            <material name="blue"/>
        </visual>
        <collision>
            <geometry>
                <cylinder radius="0.06" length="0.04"/>
            </geometry>
            <material name="blue"/>
        </collision>
        <xacro:inertial_cylinder mass="0.1" length="0.04" radius="0.06">
            <origin xyz="0 0 0" rpy="0 0 0"/>
        </xacro:inertial_cylinder>
    </link>



</robot>